//
//  FutureExtensionsTests.swift
//  FutureLib
//
//  Created by Andreas Grosam on 08/09/15.
//  Copyright Â© 2015 Andreas Grosam. All rights reserved.
//

import XCTest
import FutureLib

class FutureExtensionsTests: XCTestCase {

    override func setUp() {
        super.setUp()
        // Put setup code here. This method is called before the invocation of each test method in the class.
    }
    
    override func tearDown() {
        // Put teardown code here. This method is called after the invocation of each test method in the class.
        super.tearDown()
    }

    
    
    func testClassMethodFailedReturnsRejectedFuture() {
        let future = Future<Int>.failed(TestError.Failed)
        XCTAssertTrue(future.isCompleted)
        XCTAssert(future.isFailure)
        XCTAssertNotNil(future.result)
        if let r = future.result {
            XCTAssertTrue(r.isFailure)
            do {
                let v = try r.value()
                print("\(v)")
            }
            catch TestError.Failed {
            }
            catch {
                XCTFail("unexpected error")
            }
        }
    }

    
    func testClassMethodSucceededReturnsFulfilledFuture() {
        let future = Future.succeeded(1)
        XCTAssertTrue(future.isCompleted)
        XCTAssert(future.isSuccess)
        XCTAssertNotNil(future.result)
        if let r = future.result {
            XCTAssertTrue(r.isSuccess)
            do {
                let v = try r.value()
                XCTAssertEqual(1, v)
            }
            catch {
                XCTFail("unexpected error")
            }
        }
    }
    
    
    func testClassMethodFailedAfterReturnsAFutureWhichBecomesFailedAfterTheDelay() {
        let expect1 = self.expectationWithDescription("continuation should be called")
        let future = Future<Int>.failedAfter(0.1, error: TestError.Failed)
        future.onComplete { r in
            if let r = future.result {
                XCTAssertTrue(r.isFailure)
                do {
                    let v = try r.value()
                    print("\(v)")
                }
                catch TestError.Failed {
                }
                catch {
                    XCTFail("unexpected error")
                }
            }
            expect1.fulfill()
        }
        waitForExpectationsWithTimeout(0.12, handler: nil)
    }
    
    func testClassMethodSucceededAfterReturnsAFutureWhichBecomesSucceededAfterTheDelay() {
        let expect1 = self.expectationWithDescription("continuation should be called")
        let future = Future<Int>.succeededAfter(0.1, value: 1)
        future.onComplete { r in
            if let r = future.result {
                XCTAssertTrue(r.isSuccess)
                do {
                    let v = try r.value()
                    XCTAssertEqual(1, v)
                }
                catch {
                    XCTFail("unexpected error")
                }
            }
            expect1.fulfill()
        }
        waitForExpectationsWithTimeout(0.12, handler: nil)
    }
    
    func testCancellingClassMethodFailedAfterReturnsAFutureWhichBecomesRejectedWithACancellationError() {
        let expect1 = self.expectationWithDescription("continuation should be called")
        let cr1 = CancellationRequest()
        let future = Future<Int>.failedAfter(10, cancellationToken: cr1.token, error: TestError.Failed)
        future.onComplete { r in
            if let r = future.result {
                XCTAssertTrue(r.isFailure)
                do {
                    let _ = try r.value()
                    XCTFail("unexpected success")
                }
                catch CancellationError.Cancelled {
                }
                catch {
                    XCTFail("unexpected error")
                }
            }
            expect1.fulfill()
        }
        cr1.cancel()
        waitForExpectationsWithTimeout(0.1, handler: nil)
    }
    

    func testCancellingClassMethodSucceededAfterReturnsAFutureWhichBecomesRejectedWithACancellationError() {
        let expect1 = self.expectationWithDescription("continuation should be called")
        let cr1 = CancellationRequest()
        let future = Future<Int>.succeededAfter(10, cancellationToken: cr1.token, value: 1)
        future.onComplete { r in
            if let r = future.result {
                XCTAssertTrue(r.isFailure)
                do {
                    let _ = try r.value()
                    XCTFail("unexpected success")
                }
                catch CancellationError.Cancelled {
                }
                catch {
                    XCTFail("unexpected error")
                }
            }
            expect1.fulfill()
        }
        cr1.cancel()
        waitForExpectationsWithTimeout(0.1, handler: nil)
    }
    
    
    
    // extension CollectionType
    // Sequences of Futures
    
    func testSequenceOfFuturesShallInvokeContinuationWhenAllCompleted1() {
        let expect1 = self.expectationWithDescription("continuation should be called")
        [   Future<Int>.succeededAfter(0.1, value: 0),
            Future<Int>.succeededAfter(0.2, value: 1),
            Future<Int>.succeededAfter(0.3, value: 2)
        ]
        .onAllComplete { s -> () in
            let values = s.map() { try! $0.value() }
            print("\(values)")
            expect1.fulfill()
        }
        waitForExpectationsWithTimeout(1.0, handler: nil)
    }
    
    func testSequenceOfFuturesShallInvokeContinuationWhenAllCompleted2() {
        let expect1 = self.expectationWithDescription("continuation should be called")
        [Future<Int>.succeededAfter(0.1, value: 0),
         Future<Int>.failedAfter(0.2, error: TestError.Failed),
         Future<Int>.succeededAfter(0.3, value: 2)
        ]
        .onAllComplete { s -> () in
            print("\(s.map() { $0 })")
            expect1.fulfill()
        }
        
        waitForExpectationsWithTimeout(1.0, handler: nil)
    }
    
}
